{
  "xsize": 16,
  "zsize": 16,
  "slices": [
    [
      "#QQQQQQQQQQQQQQ#",
      "Q##############Q",
      "Q##############Q",
      "Q##############Q",
      "Q##############Q",
      "Q##############Q",
      "Q##############Q",
      "Q##############Q",
      "Q##############Q",
      "Q##############Q",
      "Q#########  ###Q",
      "Q#########  ###Q",
      "Q#########  ###Q",
      "Q#########cc###Q",
      "Q##############Q",
      "#QQQQQQQQQQQQQQ#"
    ],
    [
      "#aa#aa#aa#aa#aa#",
      "a     #  F     a",
      "a     Q        a",
      "#F    Q        #",
      "a     Q        a",
      "a     Q        a",
      "#F    #        #",
      "a              a",
      "a         cc   a",
      "#F    #  :dd:  #",
      "a     Q  :  :  a",
      "a     Q  :  :  a",
      "#     Q  :  :  #",
      "a     Q        a",
      "a     #        a",
      "#aa#aa#aa#aa#aa#"
    ],
    [
      "#aa#aa#aa#aa#aa#",
      "a     #        a",
      "a     Q        a",
      "#     Q        #",
      "a     Q        a",
      "a     Q        a",
      "#     #        #",
      "a              a",
      "a              a",
      "#     #   cc   #",
      "a     Q   dd   a",
      "a     Q        a",
      "#     Q        #",
      "a     Q        a",
      "a     #        a",
      "#aa#aa#aa#aa#aa#"
    ],
    [
      "#aa#aa#aa#aa#aa#",
      "a     #        a",
      "a     Q        a",
      "#     Q        #",
      "a     Q        a",
      "a     Q        a",
      "#     #        #",
      "a     #        a",
      "a     #        a",
      "#     #        #",
      "a     Q   cc   a",
      "a     Q   dd   a",
      "#     Q        #",
      "a     Q        a",
      "a     #        a",
      "#aa#aa#aa#aa#aa#"
    ],
    [
      "#QQQQQQQQQQQQQQ#",
      "Q##############Q",
      "Q##############Q",
      "Q##############Q",
      "Q##############Q",
      "Q##############Q",
      "Q##############Q",
      "Q##############Q",
      "Q#########  ###Q",
      "Q#########  ###Q",
      "Q#########  ###Q",
      "Q#########cc###Q",
      "Q##############Q",
      "Q##############Q",
      "Q##############Q",
      "#QQQQQQQQQQQQQQ#"
    ],
    [
      "################",
      "################",
      "################",
      "################",
      "################",
      "################",
      "################",
      "################",
      "################",
      "##########  ####",
      "##########  ####",
      "##########  ####",
      "##########cc####",
      "################",
      "################",
      "################"
    ]
  ]
}