{
  "xsize": 16,
  "zsize": 16,
  "slices": [
    [
      "#QQQQQQQQQQQQQQ#",
      "Q##############Q",
      "Q##############Q",
      "Q##############Q",
      "Q##############Q",
      "Q##############Q",
      "Q##############Q",
      "Q##############Q",
      "Q##############Q",
      "Q##############Q",
      "Q#########  ###Q",
      "Q#########  ###Q",
      "Q#########  ###Q",
      "Q#########cc###Q",
      "Q##############Q",
      "#QQQQQQQQQQQQQQ#"
    ],
    [
      "#aa#aa#aa#aa#aa#",
      "a  F  :        a",
      "a     :        a",
      "#F T  #        #",
      "a     :        a",
      "a     :        a",
      "#::#  #        #",
      "a              a",
      "a         cc   a",
      "#     #  :dd:  #",
      "a     :  :  :  a",
      "a     :  :  :  a",
      "#     #  :  :  #",
      "a     :        a",
      "a     :        a",
      "#aa#aa#aa#aa#aa#"
    ],
    [
      "#aa#aa#aa#aa#aa#",
      "a     :        a",
      "a     :        a",
      "#     #        #",
      "a     :        a",
      "a     :        a",
      "#::#  #        #",
      "a              a",
      "a              a",
      "#     #   cc   #",
      "a     :   dd   a",
      "a     :        a",
      "#     #        #",
      "a     :        a",
      "a     :        a",
      "#aa#aa#aa#aa#aa#"
    ],
    [
      "#aa#aa#aa#aa#aa#",
      "a     :        a",
      "a     :        a",
      "#     #        #",
      "a     :        a",
      "a     :        a",
      "#::#  #        #",
      "a              a",
      "a              a",
      "#     #        #",
      "a     :   cc   a",
      "a     :   dd   a",
      "#     #        #",
      "a     :        a",
      "a     :        a",
      "#aa#aa#aa#aa#aa#"
    ],
    [
      "#QQQQQQQQQQQQQQ#",
      "Q##############Q",
      "Q##############Q",
      "Q##############Q",
      "Q##############Q",
      "Q##############Q",
      "Q##############Q",
      "Q##############Q",
      "Q#########  ###Q",
      "Q#########  ###Q",
      "Q#########  ###Q",
      "Q#########cc###Q",
      "Q##############Q",
      "Q##############Q",
      "Q##############Q",
      "#QQQQQQQQQQQQQQ#"
    ],
    [
      "################",
      "################",
      "################",
      "################",
      "################",
      "################",
      "################",
      "################",
      "################",
      "##########  ####",
      "##########  ####",
      "##########  ####",
      "##########cc####",
      "################",
      "################",
      "################"
    ]
  ]
}