{
  "xsize": 16,
  "zsize": 16,
  "slices": [
    [
      "#QQQQQQQQQQQQQQ#",
      "Q##############Q",
      "Q##############Q",
      "Q##############Q",
      "Q##############Q",
      "Q##############Q",
      "Q#####1########Q",
      "Q##############Q",
      "Q##############Q",
      "Q##############Q",
      "Q#########  ###Q",
      "Q#########  ###Q",
      "Q#########  ###Q",
      "Q#########cc###Q",
      "Q##############Q",
      "#QQQQQQQQQQQQQQ#"
    ],
    [
      "#aa#aa#aa#aa#aa#",
      "a     #        a",
      "a     #        a",
      "#C             #",
      "a     #        a",
      "a     #        a",
      "#######        #",
      "a    Q#        a",
      "a    Q#   cc   a",
      "#    Q#  :dd:  #",
      "a     #  :  :  a",
      "a        :  :  a",
      "#    F#  :  :  #",
      "a    F#        a",
      "a     #        a",
      "#aa#aa#aa#aa#aa#"
    ],
    [
      "#aa#aa#aa#aa#aa#",
      "a     #        a",
      "a     #        a",
      "#              #",
      "a     #        a",
      "a     #        a",
      "##:::##T       #",
      "a     #        a",
      "a    *#        a",
      "#    *#   cc   #",
      "a     #   dd   a",
      "a              a",
      "#     #        #",
      "a     #        a",
      "a     #        a",
      "#aa#aa#aa#aa#aa#"
    ],
    [
      "#aa#aa#aa#aa#aa#",
      "a     #        a",
      "a     #        a",
      "#     #        #",
      "a     #        a",
      "a     #        a",
      "#######        #",
      "a     #        a",
      "a     #        a",
      "#     #        #",
      "a     #   cc   a",
      "a     #   dd   a",
      "#     #        #",
      "a     #        a",
      "a     #        a",
      "#aa#aa#aa#aa#aa#"
    ],
    [
      "#QQQQQQQQQQQQQQ#",
      "Q##############Q",
      "Q##############Q",
      "Q##############Q",
      "Q##############Q",
      "Q##############Q",
      "Q##############Q",
      "Q##############Q",
      "Q#########  ###Q",
      "Q#########  ###Q",
      "Q#########  ###Q",
      "Q#########cc###Q",
      "Q##############Q",
      "Q##############Q",
      "Q##############Q",
      "#QQQQQQQQQQQQQQ#"
    ],
    [
      "################",
      "################",
      "################",
      "################",
      "################",
      "################",
      "################",
      "################",
      "################",
      "##########  ####",
      "##########  ####",
      "##########  ####",
      "##########cc####",
      "################",
      "################",
      "################"
    ]
  ]
}