{
  "xsize": 16,
  "zsize": 16,
  "palette": {
    "palette": [
      {
        "char": "D",
        "block": "minecraft:iron_door[half=lower]"
      },
      {
        "char": "d",
        "block": "minecraft:iron_door[half=upper]"
      },
      {
        "char": "P",
        "block": "minecraft:light_gray_concrete"
      },
      {
        "char": "B",
        "block": "minecraft:barrel[facing=north]"
      },
      {
        "char": "c",
        "block": "factory_blocks:factory"
      },
      {
        "char": "1",
        "block": "minecraft:exposed_cut_copper_stairs[facing=north]"
      },
      {
        "char": "2",
        "block": "minecraft:exposed_cut_copper_stairs[facing=west]"
      },
      {
        "char": "3",
        "block": "minecraft:exposed_cut_copper_stairs[facing=south]"
      },
      {
        "char": "4",
        "block": "minecraft:exposed_cut_copper_stairs[facing=east]"
      }
    ]
  },
  "slices": [
    [
      "                ",
      "                ",
      "                ",
      "   ############ ",
      "   ############ ",
      "   ############ ",
      "   ##########   ",
      "   ##########   ",
      "   ##########   ",
      "   ##########   ",
      "   ##########   ",
      "   ##########   ",
      "   ##########   ",
      "                ",
      "                ",
      "                "
    ],
    [
      "                ",
      "                ",
      "                ",
      "   ############ ",
      "   ############ ",
      "   ############ ",
      "   ##########   ",
      "   ##########   ",
      "   ##########   ",
      "   ##########   ",
      "   ##########   ",
      "   ##########   ",
      "   ##########   ",
      "                ",
      "                ",
      "                "
    ],
    [
      "                ",
      "                ",
      "                ",
      "   ############ ",
      "   ############ ",
      "   ############ ",
      "   ##########   ",
      "   ##########   ",
      "   ##########   ",
      "   ##########   ",
      "   ##########   ",
      "   ##########   ",
      "   ##########   ",
      "                ",
      "                ",
      "                "
    ],
    [
      "                ",
      "                ",
      "                ",
      "   cPPPPPPPPc   ",
      "   P    B   P:  ",
      "   P        P   ",
      "   P        P   ",
      "   PC       P   ",
      "   P        P   ",
      "   P        P   ",
      "   P        P   ",
      "   P        P   ",
      "   cPDPPPPPPc   ",
      "                ",
      "                ",
      "                "
    ],
    [
      "                ",
      "                ",
      "                ",
      "   cPPPPPPPPc   ",
      "   P        P:  ",
      "   P        P   ",
      "   P        P   ",
      "   P        P   ",
      "   P        :   ",
      "   P        :   ",
      "   P        P   ",
      "   P        P   ",
      "   cPdPPP:PPc   ",
      "                ",
      "                ",
      "                "
    ],
    [
      "                ",
      "                ",
      "                ",
      "   cPPPPPPPPc   ",
      "   P        P:  ",
      "   P        P   ",
      "   P        P   ",
      "   P        P   ",
      "   P        P   ",
      "   P        P   ",
      "   P        P   ",
      "   P        P   ",
      "   cPPPPPPPPc   ",
      "                ",
      "                ",
      "                "
    ],
    [
      "                ",
      "                ",
      "                ",
      "   c11111111c   ",
      "   2########cc  ",
      "   2########4   ",
      "   2########4   ",
      "   2########4   ",
      "   2########4   ",
      "   2########4   ",
      "   2########4   ",
      "   2########4   ",
      "   c33333333c   ",
      "                ",
      "                ",
      "                "
    ],
    [
      "                ",
      "                ",
      "                ",
      "                ",
      "                ",
      "     :    :     ",
      "                ",
      "                ",
      "                ",
      "                ",
      "     :    :     ",
      "                ",
      "                ",
      "                ",
      "                ",
      "                "
    ]
  ]
}