{
  "xsize": 16,
  "zsize": 16,
  "slices": [
    [
      "##vQvQvQvQvQvQvQ",
      "##QvQvQvQvQvQvQv",
      " #vQvQvQvQvQvQvQ",
      " #QvQvQvQvQvQvQv",
      " #vQvQvQvQvQvQvQ",
      "##QvQvQvQvQvQvQv",
      "aQvQvQvQvQvQvQvQ",
      "avQvQvQvQvQvQvQv",
      "aQvQvQvQvQvQvQvQ",
      "avQvQvQvQvQvQvQv",
      "##vQvQvQvQvQvQvQ",
      " #QvQvQvQvQvQvQv",
      " #vQvQvQvQvQvQvQ",
      " #QvQvQvQvQvQvQv",
      "######vQvQ######",
      "##   #aaaa#   ##"
    ],
    [
      "##              ",
      "##              ",
      " a              ",
      " a              ",
      " a              ",
      "##              ",
      "a               ",
      "a       T       ",
      "a               ",
      "a               ",
      "##              ",
      " a              ",
      " a              ",
      " a              ",
      "##aaa#    #aaa##",
      "##   #aaaa#   ##"
    ],
    [
      "##              ",
      "##              ",
      " a              ",
      " a              ",
      " a              ",
      "##              ",
      "a               ",
      "a               ",
      "a               ",
      "a               ",
      "##              ",
      " a              ",
      " a              ",
      " a              ",
      "##aaa#    #aaa##",
      "##   #aaaa#   ##"
    ],
    [
      "##              ",
      "##              ",
      " a              ",
      " a              ",
      " a              ",
      "##              ",
      "a               ",
      "a               ",
      "a               ",
      "a               ",
      "##              ",
      " a              ",
      " a              ",
      " a              ",
      "##aaa#    #aaa##",
      "##   #aaaa#   ##"
    ],
    [
      "##              ",
      "##              ",
      " a              ",
      " a              ",
      " a              ",
      "##              ",
      "a               ",
      "a               ",
      "a               ",
      "a               ",
      "##              ",
      " a              ",
      " a              ",
      " a              ",
      "##aaa#    #aaa##",
      "##   #aaaa#   ##"
    ],
    [
      "################",
      "################",
      " ###############",
      " ###############",
      " ###############",
      "################",
      "a###############",
      "a###############",
      "a###############",
      "a###############",
      "################",
      " ###############",
      " ###############",
      " ###############",
      "################",
      "##   #aaaa#   ##"
    ]
  ]
}