{
  "xsize": 16,
  "zsize": 16,
  "slices": [
    [
      "##   #aaaa#   ##",
      "######QvQv######",
      " #vQvQvQvQvQvQvQ",
      " #QvQvQvQvQvQvQv",
      " #vQvQvQvQvQvQvQ",
      "##QvQvQvQvQvQvQv",
      "aQvQvQvQvQvQvQvQ",
      "avQvQvQvQvQvQvQv",
      "aQvQvQvQvQvQvQvQ",
      "avQvQvQvQvQvQvQv",
      "##vQvQvQvQvQv  Q",
      " #QvQvQvQvQvQ  v",
      " #vQvQvQvQvQv  Q",
      " #QvQvQvQvQvQ  v",
      "##vQvQvQvQvQv))Q",
      "##QvQvQvQvQvQvQv"
    ],
    [
      "##   #aaaa#   ##",
      "##aaa#    #aaa##",
      " a              ",
      " a              ",
      " a              ",
      "##              ",
      "a               ",
      "a               ",
      "a               ",
      "a            )) ",
      "#########   Q  Q",
      " a CC #1#   Q  Q",
      " a    #1#   Q  Q",
      " a    #1#   Q  Q",
      "### #####   Q  Q",
      "##              "
    ],
    [
      "##   #aaaa#   ##",
      "##aaa#    #aaa##",
      " a              ",
      " a              ",
      " a              ",
      "##              ",
      "a               ",
      "a               ",
      "a               ",
      "a    T          ",
      "#########   a))a",
      " a    ###   a  a",
      " a    ###   a  a",
      " a    ###   a  a",
      "### #####   a  a",
      "##              "
    ],
    [
      "##   #aaaa#   ##",
      "##aaa#    #aaa##",
      " a              ",
      " a              ",
      " a              ",
      "##              ",
      "a               ",
      "a               ",
      "a               ",
      "a               ",
      "#########   a  a",
      " a    #4#   a))a",
      " a    #1#   a  a",
      " a    #1#   a  a",
      "### #####   a  a",
      "##              "
    ],
    [
      "##   #aaaa#   ##",
      "##aaa#    #aaa##",
      " a              ",
      " a              ",
      " a              ",
      "##              ",
      "a               ",
      "a               ",
      "a               ",
      "a               ",
      "#########   a  a",
      " a    ###   a  a",
      " a    ###   a))a",
      " a    ###   a  a",
      "### #####   a  a",
      "##              "
    ],
    [
      "##   #aaaa#   ##",
      "################",
      " ###############",
      " ###############",
      " ###############",
      "################",
      "a###############",
      "a###############",
      "a###############",
      "a###############",
      "#############  #",
      " ############  #",
      " ############  #",
      " ############))#",
      "#############  #",
      "################"
    ]
  ]
}