{
  "xsize": 16,
  "zsize": 16,
  "slices": [
    [
      "##   #aaaa#   ##",
      "######QvQv######",
      "vQvQvQvQvQvQvQ# ",
      "QvQvQvQvQvQvQv# ",
      "vQvQvQvQvQvQvQ# ",
      "QvQvQvQvQvQvQv##",
      "vQvQvQvQvQvQvQva",
      "QvQvQvQvQvQvQvQa",
      "vQvQvQvQvQvQvQva",
      "QvQvQvQvQvQvQvQa",
      "vQvQvQvQvQvQvQ##",
      "QvQvQvQvQvQvQv# ",
      "vQvQvQvQvQvQvQ# ",
      "QvQvQvQvQvQvQv# ",
      "vQvQvQvQvQvQvQ##",
      "QvQvQvQvQvQvQv##"
    ],
    [
      "##   #aaaa#   ##",
      "##aaa#    #aaa##",
      "              a ",
      "              a ",
      "              a ",
      "   ########   ##",
      "   ++++4CC#    a",
      "          #    a",
      "          #    a",
      "   ++++4CC#    a",
      "   ########   ##",
      "              a ",
      "              a ",
      "              a ",
      "              ##",
      "              ##"
    ],
    [
      "##   #aaaa#   ##",
      "##aaa#    #aaa##",
      "              a ",
      "              a ",
      "       T      a ",
      "   ########   ##",
      "   +++++++#    a",
      "          #    a",
      "          #    a",
      "   +++++++#    a",
      "   ########   ##",
      "       T      a ",
      "              a ",
      "              a ",
      "              ##",
      "              ##"
    ],
    [
      "##   #aaaa#   ##",
      "##aaa#    #aaa##",
      "              a ",
      "              a ",
      "              a ",
      "   ########   ##",
      "   +++++++#    a",
      "          #    a",
      "          #    a",
      "   +++++++#    a",
      "   ########   ##",
      "              a ",
      "              a ",
      "              a ",
      "              ##",
      "              ##"
    ],
    [
      "##   #aaaa#   ##",
      "##aaa#    #aaa##",
      "              a ",
      "              a ",
      "              a ",
      "   ########   ##",
      "   +++++++#    a",
      "          #    a",
      "          #    a",
      "   +++++++#    a",
      "   ########   ##",
      "              a ",
      "              a ",
      "              a ",
      "              ##",
      "              ##"
    ],
    [
      "##   #aaaa#   ##",
      "################",
      "############### ",
      "############### ",
      "############### ",
      "################",
      "###############a",
      "###############a",
      "###############a",
      "###############a",
      "################",
      "############### ",
      "############### ",
      "############### ",
      "################",
      "################"
    ]
  ]
}