{
  "xsize": 16,
  "zsize": 16,
  "slices": [
    [
      "vQvQvQvQvQvQvQ##",
      "Q          vQv##",
      "v          QvQ# ",
      "Q          vQv# ",
      "v          QvQ# ",
      "Q          vQv##",
      "v          QvQva",
      "Q          vQvQa",
      "v          QvQva",
      "Q          vQvQa",
      "v          QvQ##",
      "QvQvQvQvQvQvQv# ",
      "vQvQvQvQvQvQvQ# ",
      "QvQvQvQvQvQvQv# ",
      "######vQvQ######",
      "##   #aaaa#   ##"
    ],
    [
      "::::::::::::  ##",
      ":          :  ##",
      ":          :  a ",
      ":          :  a ",
      ":          :  a ",
      ":          :  ##",
      ":          :   a",
      ":          :   a",
      ":          :   a",
      ":          :   a",
      ":          :  ##",
      "::::::::::::  a ",
      "              a ",
      "              a ",
      "##aaa#    #aaa##",
      "##   #aaaa#   ##"
    ],
    [
      "              ##",
      "              ##",
      "              a ",
      "              a ",
      "              a ",
      "              ##",
      "               a",
      "               a",
      "               a",
      "               a",
      "              ##",
      "              a ",
      "              a ",
      "              a ",
      "##aaa#    #aaa##",
      "##   #aaaa#   ##"
    ],
    [
      "              ##",
      "              ##",
      "              a ",
      "              a ",
      "              a ",
      "              ##",
      "               a",
      "               a",
      "               a",
      "               a",
      "              ##",
      "              a ",
      "              a ",
      "              a ",
      "##aaa#    #aaa##",
      "##   #aaaa#   ##"
    ],
    [
      "              ##",
      "              ##",
      "              a ",
      "              a ",
      "              a ",
      "              ##",
      "               a",
      "               a",
      "               a",
      "               a",
      "              ##",
      "              a ",
      "              a ",
      "              a ",
      "##aaa#    #aaa##",
      "##   #aaaa#   ##"
    ],
    [
      "################",
      "#          #####",
      "#          #### ",
      "#          #### ",
      "#          #### ",
      "#          #####",
      "#          ####a",
      "#          ####a",
      "#          ####a",
      "#          ####a",
      "#          #####",
      "############### ",
      "############### ",
      "############### ",
      "################",
      "##   #aaaa#   ##"
    ]
  ]
}