{
    "xsize": 16,
    "zsize": 16,
    "refpalette": "tinkers_fact_1",
    "slices": [
      [
        "       eeeeeeeee",
        "       efffffffe",
        "       efffffffe",
        "       efffffffe",
        "       effff4ffe",
        "       efffffffe",
        "       efffffffe",
        "eeeeeeeefffffffe",
        "effffffefffffffe",
        "ef4ffffffffffffe",
        "effffffffffffffe",
        "effffffffffffffe",
        "effffffffffffffe",
        "efiffffffffff4fe",
        "effffffefffffffe",
        "eeeeeeeeeeeeeeee"
      ],
      [
        "DDDDDDDDDDDDDDDD",
        "DDDDDDDDjjjjjjjD",
        "DDDDDDDDjkkmmmjD",
        "DDDDDDDDjnnknnjD",
        "DDDDDDDDjnnnnnjD",
        "DDDDDDDDjnnnnnjD",
        "DDDDDDDDjnknnkjD",
        "DDDDDDDDjDDooDjD",
        "DjjjD jjjD   DjD",
        "DjDDD   jq   rjD",
        "DjDDD   j     jD",
        "DjDDD         jD",
        "Dj DDD    DD DjD",
        "Dj      jDDDDDjD",
        "DjjjjjjjjjjjjjjD",
        "DDDDDDDDDDDDDDDD"
      ],
      [
        "                ",
        "        jsssssj ",
        "        snknnns ",
        "        snDDDns ",
        "        snDD ns ",
        "        sn   ns ",
        "        snEHHns ",
        "        sD   Ds ",
        " jssD ssj     s ",
        " sDD    s     s ",
        " ID     s     s ",
        " s            s ",
        " J            s ",
        " s      sD  DDs ",
        " jssssssssssssj ",
        "                "
      ],
      [
        "                ",
        "        jsssssj ",
        "        sDDDDDs ",
        "        sDD   s ",
        "        sD   Ds ",
        "        s     s ",
        "        s     s ",
        "        s     s ",
        " jssssssj     s ",
        " sD     s     s ",
        " J      s     s ",
        " s      s     s ",
        " J      s     s ",
        " s      s    Ds ",
        " jssssssssssssj ",
        "                "
      ],
      [
        "                ",
        "        jsMMMsj ",
        "        sD    s ",
        "        MD    M ",
        "        M     M ",
        "        M     M ",
        "        M     M ",
        "        s  NN s ",
        " jssssssj  OO s ",
        " s      s     J ",
        " J      s     J ",
        " s      s     J ",
        " J      s     J ",
        " s      s     s ",
        " jsPPPPssPPPPsj ",
        "                "
      ],
      [
        "                ",
        "        jjjjjjj ",
        "        jfffffj ",
        "        jffMMfj ",
        "        jffMMfj ",
        "        jfffffj ",
        "        jfffffj ",
        "        jffUUfj ",
        " jjjjjjjjffUUfj ",
        " jffffffjfffffj ",
        " jffffffjfffffj ",
        " jffffffjffMMfj ",
        " jffffffjffMMfj ",
        " jifffffjfffffj ",
        " jjjjjjjjjjjjjj ",
        "                "
      ]
    ]
  }
