{
  "xsize": 16,
  "zsize": 16,
  "slices": [
    [
      "################",
      "##QRQRQRQRQRQRQ#",
      "#QRQRQRQRQRQRQRQ",
      "#RQRQRQRQRQRQRQR",
      "#QRQRQRQRQRQRQRQ",
      "#RQRQRQRQRQRQRQR",
      "#QRQRQRQRQRQRQRQ",
      "#RQRQRQRQRQRQRQR",
      "#QRQRQRQRQRQRQRQ",
      "#RQRQRQRQRQRQRQR",
      "#QRQRQRQRQRQR  Q",
      "#RQRQRQRQRQRQ  R",
      "#QRQRQRQRQRQR  Q",
      "#RQRQRQRQRQRQ  R",
      "#QRQRQRQRQRQR))Q",
      "##QRQRQRQRQRQRQR"
    ],
    [
      "##::#########::#",
      "##             #",
      ":               ",
      ":               ",
      "#               ",
      "#               ",
      "#               ",
      "#               ",
      "#               ",
      "#            )) ",
      "#           Q  Q",
      "#           Q  Q",
      "#           Q  Q",
      ":           Q  Q",
      ":           Q  Q",
      "##              "
    ],
    [
      "##::#########::#",
      "##             #",
      ":               ",
      ":               ",
      "#               ",
      "#               ",
      "#               ",
      "#               ",
      "#               ",
      "#               ",
      "#           a))a",
      "#           a  a",
      "#           a  a",
      ":           a  a",
      ":           a  a",
      "##              "
    ],
    [
      "##::#########::#",
      "##             #",
      ":               ",
      ":               ",
      "#               ",
      "#               ",
      "#               ",
      "#               ",
      "#               ",
      "#               ",
      "#           a  a",
      "#           a))a",
      "#           a  a",
      ":           a  a",
      ":           a  a",
      "##              "
    ],
    [
      "##::#########::#",
      "##             #",
      ":               ",
      ":               ",
      "#               ",
      "#               ",
      "#               ",
      "#               ",
      "#               ",
      "#               ",
      "#           a  a",
      "#           a  a",
      "#           a))a",
      ":           a  a",
      ":           a  a",
      "##              "
    ],
    [
      "################",
      "################",
      "################",
      "################",
      "################",
      "################",
      "################",
      "################",
      "################",
      "################",
      "#############  #",
      "#############  #",
      "#############  #",
      "#############))#",
      "#############  #",
      "################"
    ]
  ]
}