{
  "xsize": 16,
  "zsize": 16,
  "slices": [
    [
      "##RQRQRQRQRQRQRQ",
      "#RQRQRQRQRQRQRQR",
      "#QRQRQRQRQRQRQRQ",
      "#RQRQRQRQRQRQRQR",
      "#QRQRQRQRQRQRQRQ",
      "#RQRQRQRQRQRQRQR",
      "#QRQRQRQRQRQRQRQ",
      "#RQRQRQRQRQRQRQR",
      "#QRQRQRQRQRQRQRQ",
      "#RQRQRQRQRQRQRQR",
      "#QRQRQRQRQRQRQRQ",
      "#RQRQRQRQRQRQRQR",
      "#QRQRQRQRQRQRQRQ",
      "#RQRQRQRQRQRQRQR",
      "##RQRQRQRQRQRQR#",
      "################"
    ],
    [
      "##              ",
      ":               ",
      ":               ",
      "#               ",
      "#               ",
      "#               ",
      "#               ",
      "#       T       ",
      "#               ",
      "#               ",
      "#               ",
      "#               ",
      ":               ",
      ":               ",
      "##             #",
      "##::#########::#"
    ],
    [
      "##              ",
      ":               ",
      ":               ",
      "#               ",
      "#               ",
      "#               ",
      "#               ",
      "#               ",
      "#               ",
      "#               ",
      "#               ",
      "#               ",
      ":               ",
      ":               ",
      "##             #",
      "##::#########::#"
    ],
    [
      "##              ",
      ":               ",
      ":               ",
      "#               ",
      "#               ",
      "#               ",
      "#               ",
      "#               ",
      "#               ",
      "#               ",
      "#               ",
      "#               ",
      ":               ",
      ":               ",
      "##             #",
      "##::#########::#"
    ],
    [
      "##              ",
      ":               ",
      ":               ",
      "#               ",
      "#               ",
      "#               ",
      "#               ",
      "#               ",
      "#               ",
      "#               ",
      "#               ",
      "#               ",
      ":               ",
      ":               ",
      "##             #",
      "##::#########::#"
    ],
    [
      "################",
      "################",
      "################",
      "################",
      "################",
      "################",
      "################",
      "################",
      "################",
      "################",
      "################",
      "################",
      "################",
      "################",
      "################",
      "################"
    ]
  ]
}