{
  "xsize": 16,
  "zsize": 16,
  "slices": [
    [
      "RQRQRQRQRQRQRQ##",
      "QRQRQRQRQRQRQRQ#",
      "RQRQRQRQRQRQRQR#",
      "QRQRQRQRQRQRQRQ#",
      "RQRQRQRQRQRQRQR#",
      "QRQRQRQRQRQRQRQ#",
      "RQRQRQRQRQRQRQR#",
      "QRQRQRQRQRQRQRQ#",
      "RQRQRQRQRQRQRQR#",
      "QRQRQRQRQRQRQRQ#",
      "RQRQRQRQRQRQRQR#",
      "QRQRQRQRQRQRQRQ#",
      "RQRQRQRQRQRQRQR#",
      "QRQRQRQRQRQRQRQ#",
      "#QRQRQRQRQRQRQ##",
      "################"
    ],
    [
      "              ##",
      "               :",
      "               :",
      "               #",
      "               #",
      "               #",
      "               #",
      "               #",
      "               #",
      "               #",
      "               #",
      "               #",
      "               :",
      "               :",
      "#             ##",
      "#::#########::##"
    ],
    [
      "              ##",
      "               :",
      "               :",
      "               #",
      "               #",
      "               #",
      "               #",
      "               #",
      "               #",
      "               #",
      "               #",
      "               #",
      "               :",
      "               :",
      "#             ##",
      "#::#########::##"
    ],
    [
      "              ##",
      "               :",
      "               :",
      "               #",
      "               #",
      "               #",
      "               #",
      "               #",
      "               #",
      "               #",
      "               #",
      "               #",
      "               :",
      "               :",
      "#             ##",
      "#::#########::##"
    ],
    [
      "              ##",
      "               :",
      "               :",
      "               #",
      "               #",
      "               #",
      "               #",
      "               #",
      "               #",
      "               #",
      "               #",
      "               #",
      "               :",
      "               :",
      "#             ##",
      "#::#########::##"
    ],
    [
      "################",
      "################",
      "################",
      "################",
      "################",
      "################",
      "################",
      "################",
      "################",
      "################",
      "################",
      "################",
      "################",
      "################",
      "################",
      "################"
    ]
  ]
}