{
  "xsize": 16,
  "zsize": 16,
  "slices": [
    [
      "################",
      "##QRQRQRQRQRQRQ#",
      "#QRQRQRQRQRQRQRQ",
      "#RQRQRQRQRQRQRQR",
      "#QRQRQRQRQRQRQRQ",
      "#RQRQRQRQRQRQRQR",
      "#QRQRQRQRQRQRQRQ",
      "#RQRQRQRQRQRQRQR",
      "#QRQRQRQRQRQRQRQ",
      "#RQRQRQRQRQRQRQR",
      "#QRQRQRQRQRQR  Q",
      "#RQRQRQRQRQRQ  R",
      "#QRQRQRQRQRQR  Q",
      "#RQRQRQRQRQRQ  R",
      "#QRQRQRQRQRQR))Q",
      "##QRQRQRQRQRQRQR"
    ],
    [
      "##aaaaaaaaaaaaa#",
      "##             #",
      "a               ",
      "a               ",
      "a               ",
      "a               ",
      "a               ",
      "a               ",
      "a               ",
      "a            )) ",
      "a           Q  Q",
      "a           Q  Q",
      "a           Q  Q",
      "a           Q  Q",
      "a           Q  Q",
      "##              "
    ],
    [
      "##aaaaaaaaaaaaa#",
      "##             #",
      "a               ",
      "a               ",
      "a               ",
      "a               ",
      "a               ",
      "a               ",
      "a               ",
      "a               ",
      "a           a))a",
      "a           a  a",
      "a           a  a",
      "a           a  a",
      "a           a  a",
      "##              "
    ],
    [
      "##aaaaaaaaaaaaa#",
      "##             #",
      "a               ",
      "a               ",
      "a               ",
      "a               ",
      "a               ",
      "a               ",
      "a               ",
      "a               ",
      "a           a  a",
      "a           a))a",
      "a           a  a",
      "a           a  a",
      "a           a  a",
      "##              "
    ],
    [
      "##aaaaaaaaaaaaa#",
      "##             #",
      "a               ",
      "a               ",
      "a               ",
      "a               ",
      "a               ",
      "a               ",
      "a               ",
      "a               ",
      "a           a  a",
      "a           a  a",
      "a           a))a",
      "a           a  a",
      "a           a  a",
      "##              "
    ],
    [
      "################",
      "################",
      "################",
      "################",
      "################",
      "################",
      "################",
      "################",
      "################",
      "################",
      "#############  #",
      "#############  #",
      "#############  #",
      "#############))#",
      "#############  #",
      "################"
    ]
  ]
}