{
  "xsize": 16,
  "zsize": 16,
  "slices": [
    [
      "##::#aaaaaa#::##",
      "#####RQRQRQ#####",
      ":#RQRQRQRQRQRQRQ",
      ":#QRQRQRQRQRQRQR",
      "##RQRQRQRQRQRQRQ",
      "aRQRQRQRQRQRQRQR",
      "aQRQRQRQRQRQRQRQ",
      "aRQRQRQRQRQRQRQR",
      "aQRQRQRQRQRQRQRQ",
      "aRQRQRQRQRQRQRQR",
      "aQRQRQRQRQRQR  Q",
      "##QRQRQRQRQRQ  R",
      ":#RQRQRQRQRQR  Q",
      ":#QRQRQRQRQRQ  R",
      "##RQRQRQRQRQR))Q",
      "##QRQRQRQRQRQRQR"
    ],
    [
      "##::#aaaaaa#::##",
      "##aa#      #aa##",
      ":a              ",
      ":a              ",
      "##              ",
      "a               ",
      "a               ",
      "a               ",
      "a               ",
      "a            )) ",
      "a           Q  Q",
      "##          Q  Q",
      ":a          Q  Q",
      ":a          Q  Q",
      "##          Q  Q",
      "##              "
    ],
    [
      "##::#aaaaaa#::##",
      "##aa#      #aa##",
      ":a              ",
      ":a              ",
      "##              ",
      "a               ",
      "a               ",
      "a               ",
      "a               ",
      "a               ",
      "a           a))a",
      "##          a  a",
      ":a          a  a",
      ":a          a  a",
      "##          a  a",
      "##              "
    ],
    [
      "##::#aaaaaa#::##",
      "##aa#      #aa##",
      ":a              ",
      ":a              ",
      "##              ",
      "a               ",
      "a               ",
      "a               ",
      "a               ",
      "a               ",
      "a           a  a",
      "##          a))a",
      ":a          a  a",
      ":a          a  a",
      "##          a  a",
      "##              "
    ],
    [
      "##::#aaaaaa#::##",
      "##aa#      #aa##",
      ":a              ",
      ":a              ",
      "##              ",
      "a               ",
      "a               ",
      "a               ",
      "a               ",
      "a               ",
      "a           a  a",
      "##          a  a",
      ":a          a))a",
      ":a          a  a",
      "##          a  a",
      "##              "
    ],
    [
      "##::#aaaaaa#::##",
      "################",
      ":###############",
      ":###############",
      "################",
      "a###############",
      "a###############",
      "a###############",
      "a###############",
      "a###############",
      "a############  #",
      "#############  #",
      ":############  #",
      ":############))#",
      "#############  #",
      "################"
    ]
  ]
}