{
  "xsize": 16,
  "zsize": 16,
  "slices": [
    [
      "################",
      "#RQRQRQRQRQRQR##",
      "RQRQRQRQRQRQRQR#",
      "QRQRQRQRQRQRQRQ#",
      "RQRQRQRQRQRQRQR#",
      "QRQRQRQRQRQRQRQ#",
      "RQRQRQRQRQRQRQR#",
      "QRQRQRQRQRQRQRQ#",
      "RQRQRQRQRQRQRQR#",
      "QRQRQRQRQRQRQRQ#",
      "RQRQRQRQRQRQRQR#",
      "QRQRQRQRQRQRQRQ#",
      "RQRQRQRQRQRQRQR#",
      "QRQRQRQRQRQRQRQ#",
      "RQRQRQRQRQRQRQR#",
      "QRQRQRQRQRQRQR##"
    ],
    [
      "#::#########::##",
      "#             ##",
      "               :",
      "               :",
      "               #",
      "               #",
      "               #",
      "               #",
      "               #",
      "               #",
      "               #",
      "               #",
      "               #",
      "               :",
      "               :",
      "              ##"
    ],
    [
      "#::#########::##",
      "#             ##",
      "               :",
      "               :",
      "               #",
      "               #",
      "               #",
      "               #",
      "               #",
      "               #",
      "               #",
      "               #",
      "               #",
      "               :",
      "               :",
      "              ##"
    ],
    [
      "#::#########::##",
      "#             ##",
      "               :",
      "               :",
      "               #",
      "               #",
      "               #",
      "               #",
      "               #",
      "               #",
      "               #",
      "               #",
      "               #",
      "               :",
      "               :",
      "              ##"
    ],
    [
      "#::#########::##",
      "#             ##",
      "               :",
      "               :",
      "               #",
      "               #",
      "               #",
      "               #",
      "               #",
      "               #",
      "               #",
      "               #",
      "               #",
      "               :",
      "               :",
      "              ##"
    ],
    [
      "################",
      "################",
      "################",
      "################",
      "################",
      "################",
      "################",
      "################",
      "################",
      "################",
      "################",
      "################",
      "################",
      "################",
      "################",
      "################"
    ]
  ]
}