{
  "xsize": 16,
  "zsize": 16,
  "slices": [
    [
      "##::#aaaaaa#::##",
      "#####RQRQRQ#####",
      "RQRQRQRQRQRQRQ#:",
      "QRQRQRQRQRQRQR#:",
      "RQRQRQRQRQRQRQ##",
      "QRQRQRQRQRQRQRQa",
      "RQRQRQRQRQRQRQRa",
      "QRQRQRQRQRQRQRQa",
      "RQRQRQRQRQRQRQRa",
      "QRQRQRQRQRQRQRQa",
      "RQRQRQRQRQRQRQRa",
      "QRQRQRQRQRQRQR##",
      "RQRQRQRQRQRQRQ#:",
      "QRQRQRQRQRQRQR#:",
      "RQRQRQRQRQRQRQ##",
      "QRQRQRQRQRQRQR##"
    ],
    [
      "##::#aaaaaa#::##",
      "##aa#      #aa##",
      "              a:",
      "              a:",
      "              ##",
      "               a",
      "               a",
      "               a",
      "               a",
      "               a",
      "               a",
      "              ##",
      "              a:",
      "              a:",
      "              ##",
      "              ##"
    ],
    [
      "##::#aaaaaa#::##",
      "##aa#      #aa##",
      "              a:",
      "              a:",
      "              ##",
      "               a",
      "               a",
      "               a",
      "               a",
      "               a",
      "               a",
      "              ##",
      "              a:",
      "              a:",
      "              ##",
      "              ##"
    ],
    [
      "##::#aaaaaa#::##",
      "##aa#      #aa##",
      "              a:",
      "              a:",
      "              ##",
      "               a",
      "               a",
      "               a",
      "               a",
      "               a",
      "               a",
      "              ##",
      "              a:",
      "              a:",
      "              ##",
      "              ##"
    ],
    [
      "##::#aaaaaa#::##",
      "##aa#      #aa##",
      "              a:",
      "              a:",
      "              ##",
      "               a",
      "               a",
      "               a",
      "               a",
      "               a",
      "               a",
      "              ##",
      "              a:",
      "              a:",
      "              ##",
      "              ##"
    ],
    [
      "##::#aaaaaa#::##",
      "################",
      "###############:",
      "###############:",
      "################",
      "###############a",
      "###############a",
      "###############a",
      "###############a",
      "###############a",
      "###############a",
      "################",
      "###############:",
      "###############:",
      "################",
      "################"
    ]
  ]
}