{
  "xsize": 16,
  "zsize": 16,
  "slices": [
    [
      "RQRQRQRQRQRQRQ##",
      "QRQRQRQRQRQRQR##",
      "RQRQRQRQRQRQRQ#:",
      "QRQRQRQRQRQRQR#:",
      "RQRQRQRQRQRQRQ##",
      "QRQRQRQRQRQRQRQa",
      "RQRQRQRQRQRQRQRa",
      "QRQRQRQRQRQRQRQa",
      "RQRQRQRQRQRQRQRa",
      "QRQRQRQRQRQRQRQa",
      "RQRQRQRQRQRQRQRa",
      "QRQRQRQRQRQRQR##",
      "RQRQRQRQRQRQRQ#:",
      "QRQRQRQRQRQRQR#:",
      "#####QRQRQR#####",
      "##::#aaaaaa#::##"
    ],
    [
      "              ##",
      "              ##",
      "              a:",
      "              a:",
      "              ##",
      "               a",
      "               a",
      "               a",
      "               a",
      "               a",
      "               a",
      "              ##",
      "              a:",
      "              a:",
      "##aa#      #aa##",
      "##::#aaaaaa#::##"
    ],
    [
      "              ##",
      "              ##",
      "              a:",
      "              a:",
      "              ##",
      "               a",
      "               a",
      "               a",
      "               a",
      "               a",
      "               a",
      "              ##",
      "              a:",
      "              a:",
      "##aa#      #aa##",
      "##::#aaaaaa#::##"
    ],
    [
      "              ##",
      "              ##",
      "              a:",
      "              a:",
      "              ##",
      "               a",
      "               a",
      "               a",
      "               a",
      "               a",
      "               a",
      "              ##",
      "              a:",
      "              a:",
      "##aa#      #aa##",
      "##::#aaaaaa#::##"
    ],
    [
      "              ##",
      "              ##",
      "              a:",
      "              a:",
      "              ##",
      "               a",
      "               a",
      "               a",
      "               a",
      "               a",
      "               a",
      "              ##",
      "              a:",
      "              a:",
      "##aa#      #aa##",
      "##::#aaaaaa#::##"
    ],
    [
      "################",
      "################",
      "###############:",
      "###############:",
      "################",
      "###############a",
      "###############a",
      "###############a",
      "###############a",
      "###############a",
      "###############a",
      "################",
      "###############:",
      "###############:",
      "################",
      "##::#aaaaaa#::##"
    ]
  ]
}