{
  "xsize": 16,
  "zsize": 16,
  "slices": [
    [
      "##RQRQRQRQRQRQRQ",
      "#RQRQRQRQRQRQRQR",
      "#QRQRQRQRQRQRQRQ",
      "#RQRQRQRQRQRQRQR",
      "#QRQRQRQRQRQRQRQ",
      "#RQRQRQRQRQRQRQR",
      "#QRQRQRQRQRQRQRQ",
      "#RQRQRQRQRQRQRQR",
      "#QRQRQRQRQRQRQRQ",
      "#RQRQRQRQRQRQRQR",
      "#QRQRQRQRQRQRQRQ",
      "#RQRQRQRQRQRQRQR",
      "#QRQRQRQRQRQRQRQ",
      "#RQRQRQRQRQRQRQR",
      "##RQRQRQRQRQRQR#",
      "################"
    ],
    [
      "##              ",
      "a               ",
      "a               ",
      "a               ",
      "a               ",
      "a               ",
      "a               ",
      "a       T       ",
      "a               ",
      "a               ",
      "a               ",
      "a               ",
      "a               ",
      "a               ",
      "##             #",
      "##aaaaaaaaaaaaa#"
    ],
    [
      "##              ",
      "a               ",
      "a               ",
      "a               ",
      "a               ",
      "a               ",
      "a               ",
      "a               ",
      "a               ",
      "a               ",
      "a               ",
      "a               ",
      "a               ",
      "a               ",
      "##             #",
      "##aaaaaaaaaaaaa#"
    ],
    [
      "##              ",
      "a               ",
      "a               ",
      "a               ",
      "a               ",
      "a               ",
      "a               ",
      "a               ",
      "a               ",
      "a               ",
      "a               ",
      "a               ",
      "a               ",
      "a               ",
      "##             #",
      "##aaaaaaaaaaaaa#"
    ],
    [
      "##              ",
      "a               ",
      "a               ",
      "a               ",
      "a               ",
      "a               ",
      "a               ",
      "a               ",
      "a               ",
      "a               ",
      "a               ",
      "a               ",
      "a               ",
      "a               ",
      "##             #",
      "##aaaaaaaaaaaaa#"
    ],
    [
      "################",
      "################",
      "################",
      "################",
      "################",
      "################",
      "################",
      "################",
      "################",
      "################",
      "################",
      "################",
      "################",
      "################",
      "################",
      "################"
    ]
  ]
}